<?xml version="1.0" encoding="utf-8"?>
<robot
  name="TRLC-DK1-Follower">
  <link
    name="base_link">
    <inertial>
      <origin
        xyz="0 0 0"
        rpy="0 0 0" />
      <mass
        value="0.02782" />
      <inertia ixx="0.001" ixy="0" ixz="0" iyy="0.001" iyz="0" izz="0.001"/>
    </inertial>
    <visual>
      <origin
        xyz="0 0 0"
        rpy="0 0 0" />
      <geometry>
        <mesh
          filename="package://dm_ht_controller/urdf/meshes/base_link.stl" />
      </geometry>
      <material
        name="">
        <color
          rgba="0.95 0.95 0.95 1" />
      </material>
    </visual>
    <collision>
      <origin
        xyz="0 0 0"
        rpy="0 0 0" />
      <geometry>
        <mesh
          filename="package://dm_ht_controller/urdf/meshes/base_link.stl" />
      </geometry>
    </collision>
  </link>
  <link
    name="link1-2">
    <inertial>
      <origin
        xyz="0 0 0"
        rpy="0 0 0" />
      <mass
        value="0.024532" />
      <inertia ixx="0.001" ixy="0" ixz="0" iyy="0.001" iyz="0" izz="0.001"/>
    </inertial>
    <visual>
      <origin
        xyz="0 0 0"
        rpy="0 0 0" />
      <geometry>
        <mesh
          filename="package://dm_ht_controller/urdf/meshes/link1-2.stl" />
      </geometry>
      <material
        name="">
        <color
          rgba="0.95 0.95 0.95 1" />
      </material>
    </visual>
    <collision>
      <origin
        xyz="0 0 0"
        rpy="0 0 0" />
      <geometry>
        <mesh
          filename="package://dm_ht_controller/urdf/meshes/link1-2.stl" />
      </geometry>
    </collision>
  </link>
  <joint
    name="joint1"
    type="revolute">
    <origin
      xyz="0 0 0.0615"
      rpy="0 0 0" />
    <parent
      link="base_link" />
    <child
      link="link1-2" />
    <axis
      xyz="0 0 1" />
    <limit
      lower="-2.0943951023931953"
      upper="2.0943951023931953"
      effort="100"
      velocity="3" />
  </joint>
  <link
    name="Link1">
    <inertial>
      <origin
        xyz="0 0 0"
        rpy="0 0 0" />
      <mass
        value="0.537601776973517" />
      <inertia ixx="0.001" ixy="0" ixz="0" iyy="0.001" iyz="0" izz="0.001"/>
    </inertial>
    <visual>
      <origin
        xyz="0 0 0"
        rpy="0 0 0" />
      <geometry>
        <mesh
          filename="package://dm_ht_controller/urdf/meshes/Link1.stl" />
      </geometry>
      <material
        name="">
        <color
          rgba="0.75 0.75 0.75 1" />
      </material>
    </visual>
    <collision>
      <origin
        xyz="0 0 0"
        rpy="0 0 0" />
      <geometry>
        <mesh
          filename="package://dm_ht_controller/urdf/meshes/Link1.stl" />
      </geometry>
    </collision>
  </link>
  <joint
    name="joint2"
    type="revolute">
    <origin
      xyz="0 0.02 0.0385"
      rpy="0 0 0" />
    <parent
      link="link1-2" />
    <child
      link="Link1" />
    <axis
      xyz="-1 0 0" />
    <limit
      lower="-0.0349065850398"
      upper="3.141592653589793"
      effort="100"
      velocity="3" />
  </joint>
  <link
    name="Link_2">
    <inertial>
      <origin
        xyz="0 0 0"
        rpy="0 0 0" />
      <mass
        value="0.299922094541001" />
      <inertia ixx="0.001" ixy="0" ixz="0" iyy="0.001" iyz="0" izz="0.001"/>
    </inertial>
    <visual>
      <origin
        xyz="0 0 0"
        rpy="0 0 0" />
      <geometry>
        <mesh
          filename="package://dm_ht_controller/urdf/meshes/Link_2.stl" />
      </geometry>
      <material
        name="">
        <color
          rgba="0.75 0.75 0.75 1" />
      </material>
    </visual>
    <collision>
      <origin
        xyz="0 0 0"
        rpy="0 0 0" />
      <geometry>
        <mesh
          filename="package://dm_ht_controller/urdf/meshes/Link_2.stl" />
      </geometry>
    </collision>
  </link>
  <joint
    name="joint3"
    type="revolute">
    <origin
      xyz="0 -0.264 0"
      rpy="0 0 0" />
    <parent
      link="Link1" />
    <child
      link="Link_2" />
    <axis
      xyz="1 0 0" />
    <limit
      lower="-0.0698131700797"
      upper="4.71238898038469"
      effort="100"
      velocity="3" />
  </joint>
  <link
    name="link4-5">
    <inertial>
      <origin
        xyz="0 0 0"
        rpy="0 0 0" />
      <mass
        value="0.0142938416889126" />
      <inertia ixx="0.001" ixy="0" ixz="0" iyy="0.001" iyz="0" izz="0.001"/>
    </inertial>
    <visual>
      <origin
        xyz="0 0 0"
        rpy="0 0 0" />
      <geometry>
        <mesh
          filename="package://dm_ht_controller/urdf/meshes/link4-5.stl" />
      </geometry>
      <material name="">
        <color
          rgba="0.95 0.95 0.95 1" />
      </material>
    </visual>
    <collision>
      <origin
        xyz="0 0 0"
        rpy="0 0 0" />
      <geometry>
        <mesh
          filename="package://dm_ht_controller/urdf/meshes/link4-5.stl" />
      </geometry>
    </collision>
  </link>
  <joint
    name="joint4"
    type="revolute">
    <origin
      xyz="0 0.244004 0.059971"
      rpy="0 0 0" />
    <parent
      link="Link_2" />
    <child
      link="link4-5" />
    <axis
      xyz="1 0 0" />
    <limit
      lower="-1.5707963267948966"
      upper="1.5707963267948966"
      effort="20"
      velocity="3" />
  </joint>
  <link
    name="link5-6">
    <inertial>
      <origin
        xyz="0 0 0"
        rpy="0 0 0" />
      <mass
        value="0.11909711022403" />
      <inertia ixx="0.001" ixy="0" ixz="0" iyy="0.001" iyz="0" izz="0.001"/>
    </inertial>
    <visual>
      <origin
        xyz="0 0 0"
        rpy="0 0 0" />
      <geometry>
        <mesh
          filename="package://dm_ht_controller/urdf/meshes/link5-6.stl" />
      </geometry>
      <material name="">
        <color
          rgba="0.95 0.95 0.95 1" />
      </material>
    </visual>
    <collision>
      <origin
        xyz="0 0 0"
        rpy="0 0 0" />
      <geometry>
        <mesh
          filename="package://dm_ht_controller/urdf/meshes/link5-6.stl" />
      </geometry>
    </collision>
  </link>
  <joint
    name="joint5"
    type="revolute">
    <origin
      xyz="0 0.061993 0.0375"
      rpy="0 0 0" />
    <parent
      link="link4-5" />
    <child
      link="link5-6" />
    <axis
      xyz="0 0 -1" />
    <limit
      lower="-1.57"
      upper="1.5707963267948966"
      effort="20"
      velocity="3" />
  </joint>
  <link
    name="Link6-7">
    <inertial>
      <origin
        xyz="0 0 0"
        rpy="0 0 0" />
      <mass
        value="0.289722572316062" />
      <inertia ixx="0.001" ixy="0" ixz="0" iyy="0.001" iyz="0" izz="0.001"/>
    </inertial>
    <visual>
      <origin
        xyz="0 0 0"
        rpy="0 0 0" />
      <geometry>
        <mesh
          filename="package://dm_ht_controller/urdf/meshes/Link6-7.stl" />
      </geometry>
      <material name="">
        <color
          rgba="0.25 0.25 0.25 1" />
      </material>
    </visual>
    <collision>
      <origin
        xyz="0 0 0"
        rpy="0 0 0" />
      <geometry>
        <mesh
          filename="package://dm_ht_controller/urdf/meshes/Link6-7.stl" />
      </geometry>
    </collision>
  </link>
  <joint
    name="joint6"
    type="revolute">
    <origin
      xyz="0.0 0.032 -0.0425"
      rpy="0 0 0" />
    <parent
      link="link5-6" />
    <child
      link="Link6-7" />
    <axis
      xyz="0 1 0" />
    <limit
      lower="-3.141592653589793"
      upper="3.141592653589793"
      effort="20"
      velocity="3" />
  </joint>
</robot>